Workbook

Sheet Task Notes
A1: Set 17 - Clean a food-delivery dataset, look up, pivot-style summary and mini dashboard
A2: Each task has its own worksheet (named in the 'Worksheet' column). Sample data is synthetic and created for this assignment.
A4: Task | B4: Question (summary) | C4: Worksheet | D4: What was done / answer / explanation
A5: 1 | B5: Clean dataset: remove duplicates, fix date formats, fill missing Delivery Partner. | C5: T1_Raw_Data / Orders_Clean / T1_Cleaning_Steps | D5: Raw export (80 rows) has 8 duplicate rows, three mixed text date formats and 20 blank delivery partners. Orders_Clean holds the 72-row cleaned result; the steps and Excel features used are in T1_Cleaning_Steps.
A6: 2 | B6: Match Restaurant ID with a Restaurant Details table and add the name. | C6: Orders_Clean (col J) / Restaurant_Details | D6: Restaurant_Details is on its own sheet. Column J: =INDEX(Restaurant_Details!$B$2:$B$9,MATCH(B2,Restaurant_Details!$A$2:$A$9,0)) (INDEX/MATCH used instead of XLOOKUP so it works in every Excel version).
A7: 3 | B7: Add day of week from Delivery Date. | C7: Orders_Clean (cols K, L) | D7: Formula: =TEXT(F2,"dddd") gives the day name (Monday ...); =WEEKDAY(F2,2) gives 1-7 with Monday = 1.
A8: 4 | B8: Summary of total orders and delivery charges per city + chart. | C8: T4_City_Summary / T4_Pivot | D8: Real PivotTable on T4_Pivot (City in Rows; Count of Order ID and Sum of Delivery Charge in Values); T4_City_Summary reproduces it with COUNTIFS/SUMIFS and feeds two column charts.
A9: 5 | B9: Mini dashboard: total orders, avg delivery time, top 3 restaurants, city filter. | C9: T5_Dashboard | D9: KPI cards, Top 3 restaurants (LARGE + INDEX/MATCH with a tie-breaker) and a bar chart, all driven by the City drop-down (C3). Excel Slicers cannot be generated outside Excel; to add one: click a PivotTable > Insert Slicer > City. Snapshot: Set17_Dashboard.jpg.

Sheet T1_Raw_Data
A1: Order ID | B1: Restaurant ID | C1: City | D1: Delivery Partner | E1: Order Date | F1: Delivery Date | G1: Delivery Time (min) | H1: Delivery Charge | I1: Amount
A2: SW3007 | B2: R001 | C2: Rajkot | D2: Sanjay | E2: 31/08/2026 | F2: 01/09/2026 | G2: 31 | H2: 25 | I2: 820
A3: SW3036 | B3: R002 | C3: Vadodara | E3: 2026-08-01 | F3: 2026-08-01 | G3: 39 | H3: 40 | I3: 560
A4: SW3064 | B4: R001 | C4: Vadodara | E4: 16/07/2026 | F4: 16/07/2026 | G4: 34 | H4: 50 | I4: 610
A5: SW3008 | B5: R005 | C5: Ahmedabad | D5: Imran | E5: 16/08/2026 | F5: 16/08/2026 | G5: 56 | H5: 45 | I5: 830
A6: SW3031 | B6: R007 | C6: Rajkot | D6: Dev | E6: 2026-08-07 | F6: 2026-08-07 | G6: 51 | H6: 45 | I6: 1120
A7: SW3069 | B7: R003 | C7: Mumbai | E7: 25-Jul-2026 | F7: 25-Jul-2026 | G7: 47 | H7: 30 | I7: 340
A8: SW3066 | B8: R003 | C8: Vadodara | D8: Neha | E8: 2026-08-11 | F8: 2026-08-12 | G8: 38 | H8: 45 | I8: 450
A9: SW3067 | B9: R008 | C9: Ahmedabad | E9: 04/08/2026 | F9: 05/08/2026 | G9: 26 | H9: 40 | I9: 790
A10: SW3009 | B10: R005 | C10: Mumbai | D10: Kiran | E10: 2026-09-09 | F10: 2026-09-09 | G10: 38 | H10: 25 | I10: 570
A11: SW3069 | B11: R003 | C11: Mumbai | E11: 2026-07-25 | F11: 2026-07-25 | G11: 47 | H11: 30 | I11: 340
A12: SW3016 | B12: R003 | C12: Vadodara | E12: 7-Sep-2026 | F12: 8-Sep-2026 | G12: 49 | H12: 45 | I12: 650
A13: SW3055 | B13: R002 | C13: Ahmedabad | D13: Imran | E13: 2026-08-04 | F13: 2026-08-04 | G13: 37 | H13: 50 | I13: 530
A14: SW3029 | B14: R005 | C14: Rajkot | E14: 1-Aug-2026 | F14: 2-Aug-2026 | G14: 33 | H14: 0 | I14: 1020
A15: SW3026 | B15: R001 | C15: Mumbai | D15: Imran | E15: 16-Jul-2026 | F15: 17-Jul-2026 | G15: 52 | H15: 30 | I15: 490
A16: SW3013 | B16: R002 | C16: Surat | E16: 2026-08-02 | F16: 2026-08-02 | G16: 52 | H16: 30 | I16: 1180
A17: SW3048 | B17: R003 | C17: Ahmedabad | D17: Kiran | E17: 21/07/2026 | F17: 22/07/2026 | G17: 46 | H17: 0 | I17: 260
A18: SW3001 | B18: R005 | C18: Vadodara | D18: Neha | E18: 5-Sep-2026 | F18: 6-Sep-2026 | G18: 52 | H18: 50 | I18: 500
A19: SW3072 | B19: R006 | C19: Rajkot | D19: Dev | E19: 2026-09-13 | F19: 2026-09-14 | G19: 18 | H19: 40 | I19: 1170
A20: SW3024 | B20: R002 | C20: Rajkot | D20: Kiran | E20: 02/07/2026 | F20: 02/07/2026 | G20: 57 | H20: 25 | I20: 1140
A21: SW3058 | B21: R002 | C21: Mumbai | D21: Neha | E21: 29/08/2026 | F21: 30/08/2026 | G21: 27 | H21: 0 | I21: 1010
A22: SW3050 | B22: R002 | C22: Mumbai | E22: 4-Jul-2026 | F22: 5-Jul-2026 | G22: 36 | H22: 45 | I22: 590
A23: SW3017 | B23: R007 | C23: Pune | D23: Rohan | E23: 01/09/2026 | F23: 01/09/2026 | G23: 47 | H23: 25 | I23: 440
A24: SW3056 | B24: R001 | C24: Rajkot | E24: 8-Aug-2026 | F24: 9-Aug-2026 | G24: 18 | H24: 50 | I24: 740
A25: SW3039 | B25: R007 | C25: Rajkot | D25: Rohan | E25: 2026-09-08 | F25: 2026-09-09 | G25: 37 | H25: 40 | I25: 1390
A26: SW3028 | B26: R006 | C26: Vadodara | E26: 05/07/2026 | F26: 06/07/2026 | G26: 26 | H26: 45 | I26: 1220
A27: SW3018 | B27: R004 | C27: Vadodara | D27: Neha | E27: 31/08/2026 | F27: 01/09/2026 | G27: 54 | H27: 45 | I27: 810
A28: SW3037 | B28: R005 | C28: Vadodara | D28: Kiran | E28: 2026-07-20 | F28: 2026-07-20 | G28: 54 | H28: 45 | I28: 950
A29: SW3045 | B29: R007 | C29: Rajkot | D29: Neha | E29: 20-Aug-2026 | F29: 20-Aug-2026 | G29: 33 | H29: 30 | I29: 1360
A30: SW3033 | B30: R004 | C30: Surat | D30: Imran | E30: 22/08/2026 | F30: 22/08/2026 | G30: 33 | H30: 40 | I30: 850
A31: SW3020 | B31: R004 | C31: Vadodara | D31: Dev | E31: 17/08/2026 | F31: 17/08/2026 | G31: 55 | H31: 0 | I31: 810
A32: SW3062 | B32: R004 | C32: Pune | E32: 30/08/2026 | F32: 31/08/2026 | G32: 31 | H32: 45 | I32: 740
A33: SW3041 | B33: R007 | C33: Pune | D33: Kiran | E33: 2026-09-01 | F33: 2026-09-02 | G33: 46 | H33: 25 | I33: 1110
A34: SW3014 | B34: R001 | C34: Surat | D34: Rohan | E34: 10-Aug-2026 | F34: 11-Aug-2026 | G34: 37 | H34: 30 | I34: 990
A35: SW3021 | B35: R004 | C35: Pune | D35: Sanjay | E35: 14/07/2026 | F35: 14/07/2026 | G35: 29 | H35: 40 | I35: 740
A36: SW3044 | B36: R008 | C36: Mumbai | E36: 13/09/2026 | F36: 14/09/2026 | G36: 33 | H36: 40 | I36: 1130
A37: SW3061 | B37: R003 | C37: Mumbai | D37: Kiran | E37: 11/09/2026 | F37: 12/09/2026 | G37: 32 | H37: 50 | I37: 550
A38: SW3046 | B38: R003 | C38: Rajkot | E38: 19/08/2026 | F38: 19/08/2026 | G38: 24 | H38: 40 | I38: 1260
A39: SW3032 | B39: R003 | C39: Pune | D39: Kiran | E39: 20-Jul-2026 | F39: 20-Jul-2026 | G39: 49 | H39: 30 | I39: 1370
A40: SW3071 | B40: R004 | C40: Rajkot | D40: Rohan | E40: 2026-07-23 | F40: 2026-07-23 | G40: 34 | H40: 45 | I40: 1070
...

Sheet Orders_Clean
A1: Order ID | B1: Restaurant ID | C1: City | D1: Delivery Partner | E1: Order Date | F1: Delivery Date | G1: Delivery Time (min) | H1: Delivery Charge | I1: Amount | J1: Restaurant Name | K1: Delivery Day | L1: Weekday No (Mon=1)
A2: SW3001 | B2: R005 | C2: Vadodara | D2: Neha | E2: 46270 | F2: 46271 | G2: 52 | H2: 50 | I2: 500 | J2: =INDEX(Restaurant_Details!$B$2:$B$9,MATCH(B2,Restaurant_Details!$A$2:$A$9,0)) -> Honest Restaurant | K2: =TEXT(F2,"dddd") -> Sunday | L2: =WEEKDAY(F2,2) -> 7
A3: SW3002 | B3: R004 | C3: Rajkot | D3: Dev | E3: 46218 | F3: 46218 | G3: 34 | H3: 45 | I3: 1170 | J3: =INDEX(Restaurant_Details!$B$2:$B$9,MATCH(B3,Restaurant_Details!$A$2:$A$9,0)) -> Biryani Blues | K3: =TEXT(F3,"dddd") -> Wednesday | L3: =WEEKDAY(F3,2) -> 3
A4: SW3003 | B4: R003 | C4: Pune | D4: Unassigned | E4: 46244 | F4: 46245 | G4: 30 | H4: 25 | I4: 1270 | J4: =INDEX(Restaurant_Details!$B$2:$B$9,MATCH(B4,Restaurant_Details!$A$2:$A$9,0)) -> Pizza Hut | K4: =TEXT(F4,"dddd") -> Tuesday | L4: =WEEKDAY(F4,2) -> 2
A5: SW3004 | B5: R006 | C5: Pune | D5: Unassigned | E5: 46272 | F5: 46272 | G5: 58 | H5: 0 | I5: 540 | J5: =INDEX(Restaurant_Details!$B$2:$B$9,MATCH(B5,Restaurant_Details!$A$2:$A$9,0)) -> Gwalia Sweets | K5: =TEXT(F5,"dddd") -> Monday | L5: =WEEKDAY(F5,2) -> 1
A6: SW3005 | B6: R008 | C6: Mumbai | D6: Imran | E6: 46256 | F6: 46256 | G6: 44 | H6: 45 | I6: 1320 | J6: =INDEX(Restaurant_Details!$B$2:$B$9,MATCH(B6,Restaurant_Details!$A$2:$A$9,0)) -> KFC | K6: =TEXT(F6,"dddd") -> Saturday | L6: =WEEKDAY(F6,2) -> 6
A7: SW3006 | B7: R007 | C7: Vadodara | D7: Neha | E7: 46247 | F7: 46247 | G7: 40 | H7: 0 | I7: 1370 | J7: =INDEX(Restaurant_Details!$B$2:$B$9,MATCH(B7,Restaurant_Details!$A$2:$A$9,0)) -> Wok Express | K7: =TEXT(F7,"dddd") -> Thursday | L7: =WEEKDAY(F7,2) -> 4
A8: SW3007 | B8: R001 | C8: Rajkot | D8: Sanjay | E8: 46265 | F8: 46266 | G8: 31 | H8: 25 | I8: 820 | J8: =INDEX(Restaurant_Details!$B$2:$B$9,MATCH(B8,Restaurant_Details!$A$2:$A$9,0)) -> Burger King | K8: =TEXT(F8,"dddd") -> Tuesday | L8: =WEEKDAY(F8,2) -> 2
A9: SW3008 | B9: R005 | C9: Ahmedabad | D9: Imran | E9: 46250 | F9: 46250 | G9: 56 | H9: 45 | I9: 830 | J9: =INDEX(Restaurant_Details!$B$2:$B$9,MATCH(B9,Restaurant_Details!$A$2:$A$9,0)) -> Honest Restaurant | K9: =TEXT(F9,"dddd") -> Sunday | L9: =WEEKDAY(F9,2) -> 7
A10: SW3009 | B10: R005 | C10: Mumbai | D10: Kiran | E10: 46274 | F10: 46274 | G10: 38 | H10: 25 | I10: 570 | J10: =INDEX(Restaurant_Details!$B$2:$B$9,MATCH(B10,Restaurant_Details!$A$2:$A$9,0)) -> Honest Restaurant | K10: =TEXT(F10,"dddd") -> Wednesday | L10: =WEEKDAY(F10,2) -> 3
A11: SW3010 | B11: R006 | C11: Ahmedabad | D11: Unassigned | E11: 46216 | F11: 46217 | G11: 40 | H11: 0 | I11: 740 | J11: =INDEX(Restaurant_Details!$B$2:$B$9,MATCH(B11,Restaurant_Details!$A$2:$A$9,0)) -> Gwalia Sweets | K11: =TEXT(F11,"dddd") -> Tuesday | L11: =WEEKDAY(F11,2) -> 2
A12: SW3011 | B12: R001 | C12: Mumbai | D12: Kiran | E12: 46238 | F12: 46239 | G12: 22 | H12: 50 | I12: 1060 | J12: =INDEX(Restaurant_Details!$B$2:$B$9,MATCH(B12,Restaurant_Details!$A$2:$A$9,0)) -> Burger King | K12: =TEXT(F12,"dddd") -> Wednesday | L12: =WEEKDAY(F12,2) -> 3
A13: SW3012 | B13: R003 | C13: Rajkot | D13: Sanjay | E13: 46266 | F13: 46266 | G13: 43 | H13: 25 | I13: 400 | J13: =INDEX(Restaurant_Details!$B$2:$B$9,MATCH(B13,Restaurant_Details!$A$2:$A$9,0)) -> Pizza Hut | K13: =TEXT(F13,"dddd") -> Tuesday | L13: =WEEKDAY(F13,2) -> 2
... A73: SW3072 | B73: R006 | C73: Rajkot | D73: Dev | E73: 46278 | F73: 46279 | G73: 18 | H73: 40 | I73: 1170 | J73: =INDEX(Restaurant_Details!$B$2:$B$9,MATCH(B73,Restaurant_Details!$A$2:$A$9,0)) -> Gwalia Sweets | K73: =TEXT(F73,"dddd") -> Monday | L73: =WEEKDAY(F73,2) -> 1

Sheet Restaurant_Details
A1: Restaurant ID | B1: Restaurant Name | C1: Cuisine
A2: R001 | B2: Burger King | C2: Fast Food
A3: R002 | B3: Domino's | C3: Italian
A4: R003 | B4: Pizza Hut | C4: Italian
A5: R004 | B5: Biryani Blues | C5: Indian
A6: R005 | B6: Honest Restaurant | C6: Indian
A7: R006 | B7: Gwalia Sweets | C7: Desserts
A8: R007 | B8: Wok Express | C8: Chinese
A9: R008 | B9: KFC | C9: Fast Food

Sheet T1_Cleaning_Steps
A1: Step | B1: Excel feature | C1: Result
A2: Remove duplicate rows | B2: Data > Remove Duplicates (all columns) | C2: 80 rows -> 72 rows (8 duplicates removed)
A3: Fix inconsistent date formats | B3: Data > Text to Columns > Date (or DATEVALUE); three text formats were mixed: yyyy-mm-dd, dd/mm/yyyy, d-mmm-yyyy | C3: Order Date and Delivery Date are now real dates (dd-mmm-yyyy)
A4: Fill missing Delivery Partner | B4: Home > Find & Select > Go To Special > Blanks > type Unassigned > Ctrl+Enter | C4: 20 blank partners filled with 'Unassigned'

Sheet T4_City_Summary
A1: City | B1: Total Orders | C1: Total Delivery Charges (Rs)
A2: Ahmedabad | B2: =COUNTIFS(Orders_Clean!$C$2:$C$73,A2) -> 9 | C2: =SUMIFS(Orders_Clean!$H$2:$H$73,Orders_Clean!$C$2:$C$73,A2) -> 240
A3: Surat | B3: =COUNTIFS(Orders_Clean!$C$2:$C$73,A3) -> 5 | C3: =SUMIFS(Orders_Clean!$H$2:$H$73,Orders_Clean!$C$2:$C$73,A3) -> 170
A4: Vadodara | B4: =COUNTIFS(Orders_Clean!$C$2:$C$73,A4) -> 13 | C4: =SUMIFS(Orders_Clean!$H$2:$H$73,Orders_Clean!$C$2:$C$73,A4) -> 480
A5: Rajkot | B5: =COUNTIFS(Orders_Clean!$C$2:$C$73,A5) -> 16 | C5: =SUMIFS(Orders_Clean!$H$2:$H$73,Orders_Clean!$C$2:$C$73,A5) -> 505
A6: Pune | B6: =COUNTIFS(Orders_Clean!$C$2:$C$73,A6) -> 14 | C6: =SUMIFS(Orders_Clean!$H$2:$H$73,Orders_Clean!$C$2:$C$73,A6) -> 445
A7: Mumbai | B7: =COUNTIFS(Orders_Clean!$C$2:$C$73,A7) -> 15 | C7: =SUMIFS(Orders_Clean!$H$2:$H$73,Orders_Clean!$C$2:$C$73,A7) -> 455
A8: Grand total | B8: =SUM(B2:B7) -> 72 | C8: =SUM(C2:C7) -> 2295

Sheet T5_Dashboard
B1: FOOD DELIVERY - MINI DASHBOARD
B3: City filter: | C3: All Cities | D3: =IF(C3="All Cities","*",C3) -> *
B4: TOTAL ORDERS | F4: AVG DELIVERY TIME (min) | J4: TOTAL DELIVERY CHARGES (Rs)
B5: =COUNTIFS(Orders_Clean!$C$2:$C$73,$D$3) -> 72 | F5: =IFERROR(AVERAGEIFS(Orders_Clean!$G$2:$G$73,Orders_Clean!$C$2:$C$73,$D$3),0) -> 37.972222 | J5: =SUMIFS(Orders_Clean!$H$2:$H$73,Orders_Clean!$C$2:$C$73,$D$3) -> 2295
B7: TOP 3 RESTAURANTS BY ORDERS
B8: =INDEX($B$30:$B$37,MATCH(LARGE($D$30:$D$37,1),$D$30:$D$37,0)) -> Pizza Hut | E8: =INDEX($C$30:$C$37,MATCH(LARGE($D$30:$D$37,1),$D$30:$D$37,0)) -> 13
B9: =INDEX($B$30:$B$37,MATCH(LARGE($D$30:$D$37,2),$D$30:$D$37,0)) -> Domino's | E9: =INDEX($C$30:$C$37,MATCH(LARGE($D$30:$D$37,2),$D$30:$D$37,0)) -> 11
B10: =INDEX($B$30:$B$37,MATCH(LARGE($D$30:$D$37,3),$D$30:$D$37,0)) -> Biryani Blues | E10: =INDEX($C$30:$C$37,MATCH(LARGE($D$30:$D$37,3),$D$30:$D$37,0)) -> 10
B13: Change the yellow City filter (C3): all KPIs, the Top 3 table and the chart update together (slicer substitute).
B28: Helper table (feeds Top 3 and chart; follows the city filter)
B29: Restaurant | C29: Orders | D29: Rank score
B30: Burger King | C30: =COUNTIFS(Orders_Clean!$J$2:$J$73,B30,Orders_Clean!$C$2:$C$73,$D$3) -> 9 | D30: =C30+(9/1000) -> 9.009
B31: Domino's | C31: =COUNTIFS(Orders_Clean!$J$2:$J$73,B31,Orders_Clean!$C$2:$C$73,$D$3) -> 11 | D31: =C31+(8/1000) -> 11.008
B32: Pizza Hut | C32: =COUNTIFS(Orders_Clean!$J$2:$J$73,B32,Orders_Clean!$C$2:$C$73,$D$3) -> 13 | D32: =C32+(7/1000) -> 13.007
B33: Biryani Blues | C33: =COUNTIFS(Orders_Clean!$J$2:$J$73,B33,Orders_Clean!$C$2:$C$73,$D$3) -> 10 | D33: =C33+(6/1000) -> 10.006
B34: Honest Restaurant | C34: =COUNTIFS(Orders_Clean!$J$2:$J$73,B34,Orders_Clean!$C$2:$C$73,$D$3) -> 6 | D34: =C34+(5/1000) -> 6.005
B35: Gwalia Sweets | C35: =COUNTIFS(Orders_Clean!$J$2:$J$73,B35,Orders_Clean!$C$2:$C$73,$D$3) -> 7 | D35: =C35+(4/1000) -> 7.004
B36: Wok Express | C36: =COUNTIFS(Orders_Clean!$J$2:$J$73,B36,Orders_Clean!$C$2:$C$73,$D$3) -> 9 | D36: =C36+(3/1000) -> 9.003
B37: KFC | C37: =COUNTIFS(Orders_Clean!$J$2:$J$73,B37,Orders_Clean!$C$2:$C$73,$D$3) -> 7 | D37: =C37+(2/1000) -> 7.002

Sheet T4_Pivot
A2: Filter
A4: City | B4: Data
A5: Ahmedabad | B5: Count - Order ID | C5: 9
B6: Sum - Delivery Charge | C6: 240
A7: Mumbai | B7: Count - Order ID | C7: 15
B8: Sum - Delivery Charge | C8: 455
A9: Pune | B9: Count - Order ID | C9: 14
B10: Sum - Delivery Charge | C10: 445
A11: Rajkot | B11: Count - Order ID | C11: 16
B12: Sum - Delivery Charge | C12: 505
A13: Surat | B13: Count - Order ID | C13: 5
B14: Sum - Delivery Charge | C14: 170
A15: Vadodara | B15: Count - Order ID | C15: 13
B16: Sum - Delivery Charge | C16: 480
A17: Total Count - Order ID | C17: 72
A18: Total Sum - Delivery Charge | C18: 2295
