Workbook

Sheet Task Notes
A1: Set 25 - VBA automation: formatting, cleaning, refresh button, PDF export, Power Query refresh
A2: Each task has its own worksheet (named in the 'Worksheet' column). Sample data is synthetic and created for this assignment.
A4: Task | B4: Question (summary) | C4: Worksheet | D4: What was done / answer / explanation
A5: 1 | B5: Record macro: bold headers, autofit, borders on IPL data. | C5: IPL_Data / VBA_Code | D5: FormatIPLData (recorded-style) formats the active sheet: bold row 1, continuous borders around UsedRange, auto-fit columns. Record it by doing those three steps with the recorder on.
A6: 2 | B6: VBA macro CleanPlaylistData: remove duplicates and trim spaces. | C6: Playlist_Export -> Playlist_After_Clean | D6: Macro trims every text cell (WorksheetFunction.Trim also collapses double spaces) and then calls RemoveDuplicates on all columns. 10 rows -> 6 rows; a message box reports how many duplicates were removed.
A7: 3 | B7: Button that refreshes all PivotTables and updates dashboard charts. | C7: Dashboard / VBA_Code | D7: RefreshDashboard loops through every PivotTable (RefreshTable) and chart (Chart.Refresh). AddRefreshButton creates a Form-Control button at H2 and assigns the macro (manual alternative: Developer > Insert > Button > Assign Macro).
A8: 4 | B8: Export dashboard sheet to Desktop PDF 'Zomato_Sales_Dashboard.pdf' with error handling. | C8: Dashboard / VBA_Code | D8: ExportDashboardPDF checks the sheet exists, resolves the real Desktop folder via WScript.Shell, exports with ExportAsFixedFormat inside On Error Resume Next and then tests Err.Number to show either a success or failure message.
A9: 5 | B9: ChatGPT/Copilot macro to refresh Power Query then show message box. | C9: VBA_Code | D9: Prompt used: "Write a VBA macro that refreshes a Power Query data source and then displays a message box saying 'Data refreshed successfully!'". Code pasted as RefreshPowerQueryData: turns off background refresh for query connections, RefreshAll, waits with CalculateUntilAsyncQueriesDone, then shows the message (error handler included).
A10: - | B10: How to run | C10: - | D10: Import Set25_VBA_Automation.bas (Alt+F11 > File > Import File), save the workbook as .xlsm, then run macros with Alt+F8. Macros cannot be embedded in an .xlsx.

Sheet IPL_Data
A1: Match Date | B1: Team 1 | C1: Team 2 | D1: Venue | E1: Winner
A2: 46103 | B2: Royal Challengers | C2: Chennai Super Kings | D2: Wankhede Stadium | E2: Chennai Super Kings
A3: 46106 | B3: Delhi Capitals | C3: Royal Challengers | D3: Narendra Modi Stadium | E3: Royal Challengers
A4: 46109 | B4: Chennai Super Kings | C4: Gujarat Titans | D4: M Chinnaswamy Stadium | E4: Chennai Super Kings
A5: 46112 | B5: Kolkata Knight Riders | C5: Chennai Super Kings | D5: Wankhede Stadium | E5: Chennai Super Kings
A6: 46115 | B6: Mumbai Indians | C6: Kolkata Knight Riders | D6: Eden Gardens | E6: Kolkata Knight Riders
A7: 46118 | B7: Kolkata Knight Riders | C7: Chennai Super Kings | D7: Narendra Modi Stadium | E7: Chennai Super Kings
A8: 46121 | B8: Royal Challengers | C8: Gujarat Titans | D8: Wankhede Stadium | E8: Royal Challengers
A9: 46124 | B9: Kolkata Knight Riders | C9: Royal Challengers | D9: Narendra Modi Stadium | E9: Kolkata Knight Riders
A10: 46127 | B10: Royal Challengers | C10: Kolkata Knight Riders | D10: Narendra Modi Stadium | E10: Royal Challengers
A11: 46130 | B11: Delhi Capitals | C11: Chennai Super Kings | D11: Wankhede Stadium | E11: Delhi Capitals
A12: 46133 | B12: Kolkata Knight Riders | C12: Mumbai Indians | D12: M Chinnaswamy Stadium | E12: Mumbai Indians
A13: 46136 | B13: Royal Challengers | C13: Delhi Capitals | D13: M Chinnaswamy Stadium | E13: Delhi Capitals

Sheet Playlist_Export
A1: Song | B1: Artist | C1: Album
A2: Kesariya | B2: Arijit Singh | C2: Brahmastra
A3: Shape of You | B3: Ed Sheeran | C3: Divide
A4: Blinding Lights | B4: The Weeknd | C4: After Hours
A5: Kesariya | B5: Arijit Singh | C5: Brahmastra
A6: Levitating | B6: Dua Lipa | C6: Future Nostalgia
A7: Tum Hi Ho | B7: Arijit Singh | C7: Aashiqui 2
A8: Shape of You | B8: Ed Sheeran | C8: Divide
A9: Believer | B9: Imagine Dragons | C9: Evolve
A10: Believer | B10: Imagine Dragons | C10: Evolve
A11: Tum Hi Ho | B11: Arijit Singh | C11: Aashiqui 2

Sheet Playlist_After_Clean
A1: Song | B1: Artist | C1: Album
A2: Kesariya | B2: Arijit Singh | C2: Brahmastra
A3: Shape of You | B3: Ed Sheeran | C3: Divide
A4: Blinding Lights | B4: The Weeknd | C4: After Hours
A5: Levitating | B5: Dua Lipa | C5: Future Nostalgia
A6: Tum Hi Ho | B6: Arijit Singh | C6: Aashiqui 2
A7: Believer | B7: Imagine Dragons | C7: Evolve

Sheet Sales_Data
A1: Order | B1: Product | C1: Units | D1: Revenue
A2: FK100 | B2: Boat Airdopes | C2: 4 | D2: =C2*1299 -> 5196
A3: FK101 | B3: Puma Shoes | C3: 2 | D3: =C3*2499 -> 4998
A4: FK102 | B4: Boat Airdopes | C4: 4 | D4: =C4*1299 -> 5196
A5: FK103 | B5: Air Fryer | C5: 4 | D5: =C5*7995 -> 31980
A6: FK104 | B6: Boat Airdopes | C6: 4 | D6: =C6*1299 -> 5196
A7: FK105 | B7: Redmi Phone | C7: 4 | D7: =C7*16999 -> 67996
A8: FK106 | B8: Smartwatch | C8: 5 | D8: =C8*2199 -> 10995
A9: FK107 | B9: Puma Shoes | C9: 1 | D9: =C9*2499 -> 2499
A10: FK108 | B10: Redmi Phone | C10: 1 | D10: =C10*16999 -> 16999
A11: FK109 | B11: Boat Airdopes | C11: 2 | D11: =C11*1299 -> 2598
A12: FK110 | B12: Redmi Phone | C12: 2 | D12: =C12*16999 -> 33998
A13: FK111 | B13: Redmi Phone | C13: 2 | D13: =C13*16999 -> 33998
A14: FK112 | B14: Puma Shoes | C14: 2 | D14: =C14*2499 -> 4998
A15: FK113 | B15: Redmi Phone | C15: 5 | D15: =C15*16999 -> 84995
A16: FK114 | B16: Smartwatch | C16: 5 | D16: =C16*2199 -> 10995
A17: FK115 | B17: Smartwatch | C17: 4 | D17: =C17*2199 -> 8796
A18: FK116 | B18: Puma Shoes | C18: 3 | D18: =C18*2499 -> 7497
A19: FK117 | B19: Puma Shoes | C19: 4 | D19: =C19*2499 -> 9996
A20: FK118 | B20: Air Fryer | C20: 4 | D20: =C20*7995 -> 31980
A21: FK119 | B21: Air Fryer | C21: 4 | D21: =C21*7995 -> 31980
A22: FK120 | B22: Air Fryer | C22: 4 | D22: =C22*7995 -> 31980
A23: FK121 | B23: Puma Shoes | C23: 5 | D23: =C23*2499 -> 12495
A24: FK122 | B24: Boat Airdopes | C24: 3 | D24: =C24*1299 -> 3897
A25: FK123 | B25: Air Fryer | C25: 3 | D25: =C25*7995 -> 23985
A26: FK124 | B26: Boat Airdopes | C26: 5 | D26: =C26*1299 -> 6495
A27: FK125 | B27: Smartwatch | C27: 2 | D27: =C27*2199 -> 4398
A28: FK126 | B28: Smartwatch | C28: 1 | D28: =C28*2199 -> 2199
A29: FK127 | B29: Redmi Phone | C29: 5 | D29: =C29*16999 -> 84995
A30: FK128 | B30: Puma Shoes | C30: 5 | D30: =C30*2499 -> 12495
A31: FK129 | B31: Boat Airdopes | C31: 3 | D31: =C31*1299 -> 3897
A32: FK130 | B32: Smartwatch | C32: 1 | D32: =C32*2199 -> 2199
A33: FK131 | B33: Boat Airdopes | C33: 5 | D33: =C33*1299 -> 6495
A34: FK132 | B34: Redmi Phone | C34: 1 | D34: =C34*16999 -> 16999
A35: FK133 | B35: Puma Shoes | C35: 2 | D35: =C35*2499 -> 4998
A36: FK134 | B36: Smartwatch | C36: 3 | D36: =C36*2199 -> 6597
A37: FK135 | B37: Boat Airdopes | C37: 1 | D37: =C37*1299 -> 1299
A38: FK136 | B38: Air Fryer | C38: 5 | D38: =C38*7995 -> 39975
A39: FK137 | B39: Redmi Phone | C39: 5 | D39: =C39*16999 -> 84995
A40: FK138 | B40: Puma Shoes | C40: 2 | D40: =C40*2499 -> 4998
...

Sheet Dashboard
A1: SALES DASHBOARD | H1: Run AddRefreshButton to place the 'Refresh Dashboard' button here (H2).
A3: Product | B3: Revenue (Rs)
A4: Boat Airdopes | B4: =SUMIFS(Sales_Data!$D$2:$D$41,Sales_Data!$B$2:$B$41,A4) -> 40269
A5: Redmi Phone | B5: =SUMIFS(Sales_Data!$D$2:$D$41,Sales_Data!$B$2:$B$41,A5) -> 424975
A6: Puma Shoes | B6: =SUMIFS(Sales_Data!$D$2:$D$41,Sales_Data!$B$2:$B$41,A6) -> 67473
A7: Air Fryer | B7: =SUMIFS(Sales_Data!$D$2:$D$41,Sales_Data!$B$2:$B$41,A7) -> 191880
A8: Smartwatch | B8: =SUMIFS(Sales_Data!$D$2:$D$41,Sales_Data!$B$2:$B$41,A8) -> 46179
A10: Sheet name must stay 'Dashboard' for ExportDashboardPDF.

Sheet VBA_Code
A1: VBA code - paste into a module (Alt+F11 > Insert > Module) or import the matching .bas file (File > Import File)
A3: Task | B3: Macro / VBA code
A4: 1 | B4: Sub FormatIPLData() ' Bold headers, auto-fit columns and borders around the whole table Dim ws As Worksheet Set ws = ActiveSheet ws.Rows(1).Font.Bold = True ws.UsedRange.Borders.LineStyle = xlContinuous ws.UsedRange.Columns.AutoFit End Sub
A5: 2 | B5: Sub CleanPlaylistData() ' Trims extra spaces in every text cell, then removes duplicate rows (header in row 1) Dim ws As Worksheet, rng As Range, c As Range Dim lastRow As Long, lastCol As Long, i As Long, before As Long Dim cols() As Variant Set ws = ActiveSheet lastRow = ws.Cells(ws.Rows.Count, 1).End(xlUp).Row lastCol = ws.Cells(1, ws.Columns.Count).End(xlToLeft).Column Set rng = ws.Range(ws.Cells(1, 1), ws.Cells(lastRow, lastCol)) before = lastRow - 1 For Each c In rng.Cells If VarType(c.Value) = vbString Then c.Value = Application.WorksheetFunction.Trim(c.Value) Next c ReDim cols(0 To lastCol - 1) For i = 0 To lastCol - 1 cols(i) = i + 1 Next i rng.RemoveDuplicates Columns:=cols, Header:=xlYes lastRow = ws.Cells(ws.Rows.Count, 1).End(xlUp).Row MsgBox "Duplicates removed: " & (before - (lastRow - 1)), vbInformation, "CleanPlaylistData" End Sub
A6: 3 | B6: Sub RefreshDashboard() ' Refreshes every PivotTable and chart in the workbook (run from the dashboard button) Dim ws As Worksheet, pt As PivotTable, co As ChartObject Application.ScreenUpdating = False For Each ws In ThisWorkbook.Worksheets For Each pt In ws.PivotTables pt.RefreshTable Next pt Next ws For Each ws In ThisWorkbook.Worksheets For Each co In ws.ChartObjects co.Chart.Refresh Next co Next ws Application.ScreenUpdating = True MsgBox "Dashboard refreshed.", vbInformation End Sub Sub AddRefreshButton() ' Creates the button on the active sheet and assigns RefreshDashboard to it Dim btn As Button Set btn = ActiveSheet.Buttons.Add(Range("H2").Left, Range("H2").Top, 130, 30) btn.Caption = "Refresh Dashboard" btn.OnAction = "RefreshDashboard" End Sub
A7: 4 | B7: Sub ExportDashboardPDF() ' Exports the 'Dashboard' sheet to the Desktop as Zomato_Sales_Dashboard.pdf with error handling Dim ws As Worksheet, desktopPath As String, filePath As String On Error Resume Next Set ws = ThisWorkbook.Worksheets("Dashboard") On Error GoTo 0 If ws Is Nothing Then MsgBox "Sheet 'Dashboard' was not found.", vbExclamation Exit Sub End If desktopPath = CreateObject("WScript.Shell").SpecialFolders("Desktop") filePath = desktopPath & "\Zomato_Sales_Dashboard.pdf" Err.Clear On Error Resume Next ws.ExportAsFixedFormat Type:=xlTypePDF, Filename:=filePath, Quality:=xlQualityStandard, _ IncludeDocProperties:=True, IgnorePrintAreas:=False, OpenAfterPublish:=False If Err.Number <> 0 Then MsgBox "The PDF could not be saved:" & vbCrLf & Err.Description, vbCritical Else MsgBox "PDF saved to:" & vbCrLf & filePath, vbInformation End If On Error GoTo 0 End Sub
A8: 5 | B8: Sub RefreshPowerQueryData() ' Prompt used with ChatGPT/Copilot: "Write a VBA macro that refreshes a Power Query data source ' and then displays a message box saying 'Data refreshed successfully!'" Dim cn As WorkbookConnection On Error GoTo ErrHandler For Each cn In ThisWorkbook.Connections If cn.Type = xlConnectionTypeOLEDB Then cn.OLEDBConnection.BackgroundQuery = False ' wait for completion Next cn ThisWorkbook.RefreshAll Application.CalculateUntilAsyncQueriesDone MsgBox "Data refreshed successfully!", vbInformation Exit Sub ErrHandler: MsgBox "Refresh failed: " & Err.Description, vbCritical End Sub

Sheet Sales_Pivot
A2: Filter
A4: Product | B4: Sum - Revenue
A5: Air Fryer | B5: 191880
A6: Boat Airdopes | B6: 40269
A7: Puma Shoes | B7: 67473
A8: Redmi Phone | B8: 424975
A9: Smartwatch | B9: 46179
A10: Grand Total | B10: 770776
